<?xml version="1.0" ?>
<!-- =================================================================================== -->
<!-- |    This document was autogenerated by xacro from /home/arthike/workspaces/pimouse_start/src/raspimouse_description/urdf/raspimouse.urdf.xacro | -->
<!-- |    EDITING THIS FILE BY HAND IS NOT RECOMMENDED                                 | -->
<!-- =================================================================================== -->
<robot name="raspimouse_on_gazebo" xmlns:controller="http://playerstage.sourceforge.net/gazebo/xmlschema/#controller" xmlns:interface="http://playerstage.sourceforge.net/gazebo/xmlschema/#interface" xmlns:sensor="http://playerstage.sourceforge.net/gazebo/xmlschema/#sensor">
  <material name="black">
    <color rgba="0.2 0.2 0.2 1.0"/>
  </material>
  <gazebo reference="base_link">
    <mu1>0.1</mu1>
    <mu2>0.1</mu2>
  </gazebo>
  <!-- =============== Link & Joint =============== -->
  <!-- Base -->
  <link name="base_footprint"/>
  <joint name="base_joint" type="fixed">
    <origin xyz="0 0 0.00185"/>
    <parent link="base_footprint"/>
    <child link="base_link"/>
  </joint>
  <link name="base_link">
    <visual>
      <geometry>
        <mesh filename="/home/arthike/workspaces/pimouse_start/src/raspimouse_description/meshes/dae/body/raspimouse_body.dae"/>
      </geometry>
    </visual>
    <collision>
      <!-- <geometry> -->
      <!-- <mesh filename="package://raspimouse_description/meshes/dae/body/raspimouse_body.dae" /> -->
      <!-- </geometry> -->
      <origin rpy="0 0 0" xyz="0.005 0 0.040"/>
      <geometry>
        <box size="0.117 0.080 0.080"/>
      </geometry>
    </collision>
    <inertial>
      <origin xyz="-0.005075 0.0 0.03"/>
      <mass value="0.7186"/>
      <inertia ixx="0.0007466666666666666" ixy="0" ixz="0" iyy="0.0009566666666666668" iyz="0" izz="0.0009566666666666668"/>
      <!-- <origin xyz="-0.005075 -0.000427 0.029879" /> -->
      <!-- <inertia ixx="0.001238161833" ixy="0.000000904986" iyy="0.001368529369"
                    ixz="0.000100297310" iyz="0.000022118177" izz="0.000784319117" /> -->
    </inertial>
  </link>
  <joint name="right_wheel_joint" type="continuous">
    <origin rpy="1.57 0 0" xyz="0 -0.0425 0.02215"/>
    <axis xyz="0 0 -1"/>
    <parent link="base_link"/>
    <child link="right_wheel"/>
    <limit effort="70" velocity="15"/>
    <safety_controller k_velocity="10"/>
    <dynamics damping="1.0" friction="1.0"/>
  </joint>
  <link name="right_wheel">
    <visual>
      <geometry>
        <mesh filename="/home/arthike/workspaces/pimouse_start/src/raspimouse_description/meshes/dae/wheel/raspimouse_wheel.dae"/>
      </geometry>
    </visual>
    <collision>
      <!-- <geometry> -->
      <!-- <mesh filename="package://raspimouse_description/meshes/dae/wheel/raspimouse_wheel.dae"/> -->
      <!-- </geometry> -->
      <origin xyz="0 0 0.003"/>
      <geometry>
        <cylinder length="0.01" radius="0.024"/>
      </geometry>
      <surface>
        <friction>
          <ode>
            <mu>2</mu>
            <mu2>2</mu2>
            <slip1>0</slip1>
            <slip2>0</slip2>
          </ode>
        </friction>
      </surface>
    </collision>
    /
      
    <inertial>
      <origin xyz="-0.000107 0 0.002875"/>
      <mass value="0.0113"/>
      <inertia ixx="0.000002208187" ixy="0.000000000001" ixz="0.000000004787" iyy="0.00000218412" iyz="0.000000000003" izz="0.000004078299"/>
    </inertial>
  </link>
  <joint name="left_wheel_joint" type="continuous">
    <origin rpy="-1.57 0 0" xyz="0 0.0425 0.02215"/>
    <axis xyz="0 0 1"/>
    <parent link="base_link"/>
    <child link="left_wheel"/>
    <limit effort="70" velocity="15"/>
    <safety_controller k_velocity="10"/>
    <dynamics damping="1.0" friction="1.0"/>
  </joint>
  <link name="left_wheel">
    <visual>
      <geometry>
        <mesh filename="/home/arthike/workspaces/pimouse_start/src/raspimouse_description/meshes/dae/wheel/raspimouse_wheel.dae"/>
      </geometry>
    </visual>
    <collision>
      <!-- <geometry> -->
      <!-- <mesh filename="package://raspimouse_description/meshes/dae/wheel/raspimouse_wheel.dae"/> -->
      <!-- </geometry> -->
      <origin xyz="0 0 0.003"/>
      <geometry>
        <cylinder length="0.01" radius="0.024"/>
      </geometry>
      <surface>
        <friction>
          <ode>
            <mu>2</mu>
            <mu2>2</mu2>
            <slip1>0</slip1>
            <slip2>0</slip2>
          </ode>
        </friction>
      </surface>
    </collision>
    /
      
    <inertial>
      <origin xyz="-0.000107 0 0.002875"/>
      <mass value="0.0113"/>
      <inertia ixx="0.000002208187" ixy="0.000000000001" ixz="0.000000004787" iyy="0.00000218412" iyz="0.000000000003" izz="0.000004078299"/>
    </inertial>
  </link>
  <!-- Sensors -->
  <link name="lightsensors"/>
  <joint name="lightsensors_joint" type="fixed">
    <parent link="base_link"/>
    <child link="lightsensors"/>
  </joint>
  <joint name="rf_joint" type="fixed">
    <origin rpy="0 0 0" xyz="0.04 -0.045 0.032"/>
    <parent link="lightsensors"/>
    <child link="rf_lightsensor_link"/>
  </joint>
  <link name="rf_lightsensor_link">
    <visual>
      <geometry>
        <box size="0.01 0.005 0.007"/>
      </geometry>
      <material name="Gray">
        <color rgba="0.2 0.2 0.2 1"/>
      </material>
    </visual>
    <inertial>
      <mass value="0.000001"/>
      <origin xyz="0 0 0"/>
      <inertia ixx="0.0001" ixy="0.0" ixz="0.0" iyy="0.0001" iyz="0.0" izz="0.0001"/>
    </inertial>
  </link>
  <joint name="rs_joint" type="fixed">
    <origin rpy="0 0 -1.04" xyz="0.059 -0.01 0.032"/>
    <parent link="lightsensors"/>
    <child link="rs_lightsensor_link"/>
  </joint>
  <link name="rs_lightsensor_link">
    <visual>
      <geometry>
        <box size="0.01 0.005 0.007"/>
      </geometry>
      <material name="Gray">
        <color rgba="0.2 0.2 0.2 1"/>
      </material>
    </visual>
    <inertial>
      <mass value="0.000001"/>
      <origin xyz="0 0 0"/>
      <inertia ixx="0.0001" ixy="0.0" ixz="0.0" iyy="0.0001" iyz="0.0" izz="0.0001"/>
    </inertial>
  </link>
  <joint name="ls_joint" type="fixed">
    <origin rpy="0 0 1.04" xyz="0.059 0.01 0.032"/>
    <parent link="lightsensors"/>
    <child link="ls_lightsensor_link"/>
  </joint>
  <link name="ls_lightsensor_link">
    <visual>
      <geometry>
        <box size="0.01 0.005 0.007"/>
      </geometry>
      <material name="Gray">
        <color rgba="0.2 0.2 0.2 1"/>
      </material>
    </visual>
    <inertial>
      <mass value="0.000001"/>
      <origin xyz="0 0 0"/>
      <inertia ixx="0.0001" ixy="0.0" ixz="0.0" iyy="0.0001" iyz="0.0" izz="0.0001"/>
    </inertial>
  </link>
  <joint name="lf_joint" type="fixed">
    <origin rpy="0 0 0" xyz="0.04 0.045 0.032"/>
    <parent link="lightsensors"/>
    <child link="lf_lightsensor_link"/>
  </joint>
  <link name="lf_lightsensor_link">
    <visual>
      <geometry>
        <box size="0.01 0.005 0.007"/>
      </geometry>
      <material name="Gray">
        <color rgba="0.2 0.2 0.2 1"/>
      </material>
    </visual>
    <inertial>
      <mass value="0.000001"/>
      <origin xyz="0 0 0"/>
      <inertia ixx="0.0001" ixy="0.0" ixz="0.0" iyy="0.0001" iyz="0.0" izz="0.0001"/>
    </inertial>
  </link>
  <!-- =============== Gazebo =============== -->
  <gazebo>
    <plugin filename="libgazebo_ros2_control.so" name="gazebo_ros_control">
      <robotNamespace>/</robotNamespace>
    </plugin>
  </gazebo>
  <gazebo reference="rf_lightsensor_link">
    <material>Gazebo/Gray</material>
    <sensor name="rf_lightsensor" type="ray">
      <pose>0 0 0 0 0 0</pose>
      <visualize>false</visualize>
      <update_rate>20</update_rate>
      <ray>
        <scan>
          <horizontal>
            <samples>1</samples>
            <resolution>1</resolution>
            <min_angle>-0.15</min_angle>
            <max_angle>0.15</max_angle>
          </horizontal>
        </scan>
        <range>
          <min>0.01</min>
          <max>0.6</max>
          <resolution>0.001</resolution>
        </range>
        <noise>
          <type>gaussian</type>
          <mean>0.0</mean>
          <stddev>0.01</stddev>
        </noise>
      </ray>
      <plugin filename="libgazebo_ros_laser.so" name="gazebo_ros_rf_lightsensor_controller">
        <robotNamespace>raspimouse_on_gazebo</robotNamespace>
        <topicName>rf_scan</topicName>
        <frameName>/rf</frameName>
      </plugin>
    </sensor>
  </gazebo>
  <gazebo reference="rs_lightsensor_link">
    <material>Gazebo/Gray</material>
    <sensor name="rs_lightsensor" type="ray">
      <pose>0 0 0 0 0 0</pose>
      <visualize>false</visualize>
      <update_rate>20</update_rate>
      <ray>
        <scan>
          <horizontal>
            <samples>1</samples>
            <resolution>1</resolution>
            <min_angle>-1.19</min_angle>
            <max_angle>-0.89</max_angle>
          </horizontal>
        </scan>
        <range>
          <min>0.01</min>
          <max>0.6</max>
          <resolution>0.001</resolution>
        </range>
        <noise>
          <type>gaussian</type>
          <mean>0.0</mean>
          <stddev>0.01</stddev>
        </noise>
      </ray>
      <plugin filename="libgazebo_ros_laser.so" name="gazebo_ros_rs_lightsensor_controller">
        <robotNamespace>raspimouse_on_gazebo</robotNamespace>
        <topicName>rs_scan</topicName>
        <frameName>/rs</frameName>
      </plugin>
    </sensor>
  </gazebo>
  <gazebo reference="ls_lightsensor_link">
    <material>Gazebo/Gray</material>
    <sensor name="ls_lightsensor" type="ray">
      <pose>0 0 0 0 0 0</pose>
      <visualize>false</visualize>
      <update_rate>20</update_rate>
      <ray>
        <scan>
          <horizontal>
            <samples>1</samples>
            <resolution>1</resolution>
            <min_angle>0.89</min_angle>
            <max_angle>1.19</max_angle>
          </horizontal>
        </scan>
        <range>
          <min>0.01</min>
          <max>0.6</max>
          <resolution>0.001</resolution>
        </range>
        <noise>
          <type>gaussian</type>
          <mean>0.0</mean>
          <stddev>0.01</stddev>
        </noise>
      </ray>
      <plugin filename="libgazebo_ros_laser.so" name="gazebo_ros_ls_lightsensor_controller">
        <robotNamespace>raspimouse_on_gazebo</robotNamespace>
        <topicName>ls_scan</topicName>
        <frameName>/ls</frameName>
      </plugin>
    </sensor>
  </gazebo>
  <gazebo reference="lf_lightsensor_link">
    <material>Gazebo/Gray</material>
    <sensor name="lf_lightsensor" type="ray">
      <pose>0 0 0 0 0 0</pose>
      <visualize>false</visualize>
      <update_rate>20</update_rate>
      <ray>
        <scan>
          <horizontal>
            <samples>1</samples>
            <resolution>1</resolution>
            <min_angle>-0.15</min_angle>
            <max_angle>0.15</max_angle>
          </horizontal>
        </scan>
        <range>
          <min>0.01</min>
          <max>0.6</max>
          <resolution>0.001</resolution>
        </range>
        <noise>
          <type>gaussian</type>
          <mean>0.0</mean>
          <stddev>0.01</stddev>
        </noise>
      </ray>
      <plugin filename="libgazebo_ros_laser.so" name="gazebo_ros_lf_lightsensor_controller">
        <robotNamespace>raspimouse_on_gazebo</robotNamespace>
        <topicName>lf_scan</topicName>
        <frameName>/lf</frameName>
      </plugin>
    </sensor>
  </gazebo>
  <gazebo>
    <plugin filename="libgazebo_ros_diff_drive.so" name="differential_drive_controller">
      <!-- Name of robot namespace of DiffDriveController -->
      <alwaysOn>true</alwaysOn>
      <updateRate>50</updateRate>
      <!-- Set to true to swap right and left wheels, defaults to true -->
      <legacyMode>false</legacyMode>
      <rosDebugLevel>na</rosDebugLevel>
      <!-- Name of left joint, defaults to `left_joint` -->
      <leftJoint>left_wheel_joint</leftJoint>
      <!-- Name of right joint, defaults to `right_joint` -->
      <rightJoint>right_wheel_joint</rightJoint>
      <robotBaseFrame>base_footprint</robotBaseFrame>
      <!-- Topic to receive geometry_msgs/Twist message commands, defaults to `cmd_vel` -->
      <commandTopic>cmd_vel</commandTopic>
      <!-- Topic to publish nav_msgs/Odometry messages, defaults to `odom` -->
      <odometryTopic>odom</odometryTopic>
      <!-- Odometry frame, defaults to `odom` -->
      <odometryFrame>odom</odometryFrame>
      <!-- Odometry source, 0 for ENCODER, 1 for WORLD, defaults to WORLD -->
      <odometrySource>world</odometrySource>
      <!-- Phisical wheel params -->
      <wheelSeparation>0.0925</wheelSeparation>
      <wheelDiameter>0.048</wheelDiameter>
      <!-- Maximum torque which the wheels can produce, in Nm, defaults to 5 Nm -->
      <wheelTorque>500</wheelTorque>
      <!-- Wheel acceleration, in rad/s^2, defaults to 0.0 rad/s^2 -->
      <wheelAcceleration>0</wheelAcceleration>
      <!-- Set to true to publish /odom (nav_msgs::Odometry), defaults to true -->
      <publishTf>True</publishTf>
      <!-- Set to true to publish transforms for the wheel links, defaults to false -->
      <publishWheelTF>True</publishWheelTF>
      <!-- Set to true to publish transforms for the odometry, defaults to true -->
      <publishOdomTF>True</publishOdomTF>
      <!-- Set to true to publish sensor_msgs/JointState on /joint_states for the wheel joints, defaults to false -->
      <publishWheelJointState>True</publishWheelJointState>
    </plugin>
  </gazebo>
  <raspimouse_on_gazebo/>
</robot>
